Workbook
Name Parameters: #REF!
Name Summary: #REF!

Sheet Datos Originales
A1: fecha-mes | B1: fecha-dia | C1: id_especialista | D1: horario | E1: estado | F1: tipoTurno | G1: turnoEstado (atributo Objetivo)
A2: 11 | B2: 1 | C2: 1 | D2: MAÑANA | E2: TERMINADO | F2: TURNO | G2: =+F2&"-"&E2 -> TURNO-TERMINADO
A3: 11 | B3: 1 | C3: 1 | D3: MAÑANA | E3: TERMINADO | F3: TURNO | G3: =+F3&"-"&E3 -> TURNO-TERMINADO
A4: 11 | B4: 1 | C4: 1 | D4: MAÑANA | E4: TERMINADO | F4: TURNO | G4: =+F4&"-"&E4 -> TURNO-TERMINADO
A5: 11 | B5: 1 | C5: 1 | D5: MAÑANA | E5: TERMINADO | F5: TURNO | G5: =+F5&"-"&E5 -> TURNO-TERMINADO
A6: 11 | B6: 1 | C6: 1 | D6: MAÑANA | E6: TERMINADO | F6: SOBRETURNO | G6: =+F6&"-"&E6 -> SOBRETURNO-TERMINADO
A7: 11 | B7: 1 | C7: 1 | D7: MAÑANA | E7: TERMINADO | F7: TURNO | G7: =+F7&"-"&E7 -> TURNO-TERMINADO
A8: 11 | B8: 1 | C8: 1 | D8: MAÑANA | E8: SUSPENDIDO | F8: SOBRETURNO | G8: =+F8&"-"&E8 -> SOBRETURNO-SUSPENDIDO
A9: 11 | B9: 1 | C9: 1 | D9: MAÑANA | E9: TERMINADO | F9: TURNO | G9: =+F9&"-"&E9 -> TURNO-TERMINADO
A10: 11 | B10: 1 | C10: 1 | D10: MAÑANA | E10: SUSPENDIDO | F10: SOBRETURNO | G10: =+F10&"-"&E10 -> SOBRETURNO-SUSPENDIDO
A11: 11 | B11: 1 | C11: 1 | D11: MAÑANA | E11: TERMINADO | F11: TURNO | G11: =+F11&"-"&E11 -> TURNO-TERMINADO
A12: 11 | B12: 1 | C12: 1 | D12: MAÑANA | E12: TERMINADO | F12: TURNO | G12: =+F12&"-"&E12 -> TURNO-TERMINADO
A13: 11 | B13: 1 | C13: 1 | D13: MAÑANA | E13: TERMINADO | F13: SOBRETURNO | G13: =+F13&"-"&E13 -> SOBRETURNO-TERMINADO
... A9337: 4 | B9337: 3 | C9337: 1 | D9337: TARDE | E9337: SUSPENDIDO | F9337: SOBRETURNO | G9337: =+F9337&"-"&E9337 -> SOBRETURNO-SUSPENDIDO

Sheet Res Kohonen
B1: Kohonen-SOM 1
B2: Parameters
B4: SOM parameters
B5: Columns | C5: 3
B6: Rows | C6: 3
B7: Distance normalization | C7: variance
B8: Learning rate | C8: 0.05
B9: Seed random generator | C9: Standard
B12: Results
B14: MAP Topology
C16: 1 | D16: 2 | E16: 3
B17: 1 | C17: 1397 | D17: 1125 | E17: 1354
B18: 2 | C18: 1891 | D18: 1053 | E18: 0
B19: 3 | C19: 995 | D19: 1500 | E19: 21
B21: MAP Quality
B23: Ratio explained | C23: 0.7649
B25: Cluster centroids
B27: Attribute | C27: Cluster n1 | D27: Cluster n2 | E27: Cluster n3 | F27: Cluster n4 | G27: Cluster n5 | H27: Cluster n6 | I27: Cluster n7 | J27: Cluster n8 | K27: Cluster n9
B28: fecha-mes | C28: 9.889048 | D28: 9.733333 | E28: 3.22969 | F28: 3.297197 | G28: 9.649573 | H28: -99999 | I28: 10.152764 | J28: 3.453333 | K28: 3
B29: fecha-dia | C29: 9.511095 | D29: 23.950222 | E29: 14.324963 | F29: 7.668429 | G29: 8.609687 | H29: -99999 | I29: 24.117588 | J29: 24.192667 | K29: 18.380952
B30: especialista_id | C30: 1 | D30: 1 | E30: 1 | F30: 1 | G30: 1 | H30: -99999 | I30: 1 | J30: 1 | K30: 2
B31: d2c_horario_1 | C31: 3 | D31: 1.618667 | E31: 1.343427 | F31: 2.791116 | G31: 1.559354 | H31: -99999 | I31: 3 | J31: 2.77 | K31: 3
B32: Use GROUP CHARACTERIZATION for detailed comparisons
B35: Computation time : 47 ms.
B36: Created at 30/04/2019 14:29:54

Sheet Datos Segmentados
A1: fecha-mes | B1: fecha-dia | C1: id_especialista | D1: horario | E1: estado | F1: tipoTurno | G1: turnoEstado | H1: d2c_horario_1 | I1: Cluster_SOM_1 | M1: AUXILIAR para CONTAR | P1: turnoEstado
A2: 11 | B2: 1 | C2: 1 | D2: MAÑANA | E2: TERMINADO | F2: TURNO | G2: TURNO-TERMINADO | H2: 1 | I2: c_som_2_2 | M2: =CONCATENATE(G2,"-",I2) -> TURNO-TERMINADO-c_som_2_2 | P2: TURNO-TERMINADO
A3: 11 | B3: 1 | C3: 1 | D3: MAÑANA | E3: TERMINADO | F3: TURNO | G3: TURNO-TERMINADO | H3: 1 | I3: c_som_2_2 | M3: =CONCATENATE(G3,"-",I3) -> TURNO-TERMINADO-c_som_2_2 | P3: SOBRETURNO-TERMINADO
A4: 11 | B4: 1 | C4: 1 | D4: MAÑANA | E4: TERMINADO | F4: TURNO | G4: TURNO-TERMINADO | H4: 1 | I4: c_som_2_2 | M4: =CONCATENATE(G4,"-",I4) -> TURNO-TERMINADO-c_som_2_2 | P4: SOBRETURNO-SUSPENDIDO
A5: 11 | B5: 1 | C5: 1 | D5: MAÑANA | E5: TERMINADO | F5: TURNO | G5: TURNO-TERMINADO | H5: 1 | I5: c_som_2_2 | M5: =CONCATENATE(G5,"-",I5) -> TURNO-TERMINADO-c_som_2_2 | P5: TURNO-SUSPENDIDO
A6: 11 | B6: 1 | C6: 1 | D6: MAÑANA | E6: TERMINADO | F6: SOBRETURNO | G6: SOBRETURNO-TERMINADO | H6: 1 | I6: c_som_2_2 | M6: =CONCATENATE(G6,"-",I6) -> SOBRETURNO-TERMINADO-c_som_2_2
A7: 11 | B7: 1 | C7: 1 | D7: MAÑANA | E7: TERMINADO | F7: TURNO | G7: TURNO-TERMINADO | H7: 1 | I7: c_som_2_2 | M7: =CONCATENATE(G7,"-",I7) -> TURNO-TERMINADO-c_som_2_2
A8: 11 | B8: 1 | C8: 1 | D8: MAÑANA | E8: SUSPENDIDO | F8: SOBRETURNO | G8: SOBRETURNO-SUSPENDIDO | H8: 1 | I8: c_som_2_2 | M8: =CONCATENATE(G8,"-",I8) -> SOBRETURNO-SUSPENDIDO-c_som_2_2
A9: 11 | B9: 1 | C9: 1 | D9: MAÑANA | E9: TERMINADO | F9: TURNO | G9: TURNO-TERMINADO | H9: 1 | I9: c_som_2_2 | M9: =CONCATENATE(G9,"-",I9) -> TURNO-TERMINADO-c_som_2_2
A10: 11 | B10: 1 | C10: 1 | D10: MAÑANA | E10: SUSPENDIDO | F10: SOBRETURNO | G10: SOBRETURNO-SUSPENDIDO | H10: 1 | I10: c_som_2_2 | M10: =CONCATENATE(G10,"-",I10) -> SOBRETURNO-SUSPENDIDO-c_som_2_2
A11: 11 | B11: 1 | C11: 1 | D11: MAÑANA | E11: TERMINADO | F11: TURNO | G11: TURNO-TERMINADO | H11: 1 | I11: c_som_2_2 | M11: =CONCATENATE(G11,"-",I11) -> TURNO-TERMINADO-c_som_2_2
A12: 11 | B12: 1 | C12: 1 | D12: MAÑANA | E12: TERMINADO | F12: TURNO | G12: TURNO-TERMINADO | H12: 1 | I12: c_som_2_2 | M12: =CONCATENATE(G12,"-",I12) -> TURNO-TERMINADO-c_som_2_2
A13: 11 | B13: 1 | C13: 1 | D13: MAÑANA | E13: TERMINADO | F13: SOBRETURNO | G13: SOBRETURNO-TERMINADO | H13: 1 | I13: c_som_2_2 | M13: =CONCATENATE(G13,"-",I13) -> SOBRETURNO-TERMINADO-c_som_2_2
A14: 11 | B14: 1 | C14: 1 | D14: MAÑANA | E14: TERMINADO | F14: TURNO | G14: TURNO-TERMINADO | H14: 1 | I14: c_som_2_2 | M14: =CONCATENATE(G14,"-",I14) -> TURNO-TERMINADO-c_som_2_2
A15: 11 | B15: 1 | C15: 1 | D15: MAÑANA | E15: TERMINADO | F15: SOBRETURNO | G15: SOBRETURNO-TERMINADO | H15: 1 | I15: c_som_2_2 | M15: =CONCATENATE(G15,"-",I15) -> SOBRETURNO-TERMINADO-c_som_2_2
A16: 11 | B16: 1 | C16: 1 | D16: MAÑANA | E16: TERMINADO | F16: SOBRETURNO | G16: SOBRETURNO-TERMINADO | H16: 1 | I16: c_som_2_2 | M16: =CONCATENATE(G16,"-",I16) -> SOBRETURNO-TERMINADO-c_som_2_2
A17: 11 | B17: 1 | C17: 1 | D17: MAÑANA | E17: SUSPENDIDO | F17: SOBRETURNO | G17: SOBRETURNO-SUSPENDIDO | H17: 1 | I17: c_som_2_2 | M17: =CONCATENATE(G17,"-",I17) -> SOBRETURNO-SUSPENDIDO-c_som_2_2
... A9337: 4 | B9337: 3 | C9337: 1 | D9337: TARDE | E9337: SUSPENDIDO | F9337: SOBRETURNO | G9337: SOBRETURNO-SUSPENDIDO | H9337: 3 | I9337: c_som_2_1 | M9337: =CONCATENATE(G9337,"-",I9337) -> SOBRETURNO-SUSPENDIDO-c_som_2_1

Sheet Parrilla de Elementos
B2: Cantidad de Elementos por Cluster_SOM | J2: % de elementos por Cluster_SOM
D4: TURNO-TERMINADO | E4: SOBRETURNO-TERMINADO | F4: SOBRETURNO-SUSPENDIDO | G4: TURNO-SUSPENDIDO | L4: TURNO-TERMINADO | M4: SOBRETURNO-TERMINADO | N4: SOBRETURNO-SUSPENDIDO | O4: TURNO-SUSPENDIDO
C5: c_som_1_1 | D5: =COUNTIF('Datos Segmentados'!M:M,CONCATENATE(D$4,"-",$C5)) -> 602 | E5: =COUNTIF('Datos Segmentados'!M:M,CONCATENATE(E$4,"-",$C5)) -> 706 | F5: =COUNTIF('Datos Segmentados'!M:M,CONCATENATE(F$4,"-",$C5)) -> 36 | G5: =COUNTIF('Datos Segmentados'!M:M,CONCATENATE(G$4,"-",$C5)) -> 53 | H5: =SUM(D5:G5) -> 1397 | K5: c_som_1_1 | L5: =+D5/D$14 -> 0.13121186 | M5: =+E5/E$14 -> 0.17641179 | N5: =+F5/F$14 -> 0.11501597 | O5: =+G5/G$14 -> 0.12240185
C6: c_som_1_2 | D6: =COUNTIF('Datos Segmentados'!M:M,CONCATENATE(D$4,"-",$C6)) -> 529 | E6: =COUNTIF('Datos Segmentados'!M:M,CONCATENATE(E$4,"-",$C6)) -> 479 | F6: =COUNTIF('Datos Segmentados'!M:M,CONCATENATE(F$4,"-",$C6)) -> 58 | G6: =COUNTIF('Datos Segmentados'!M:M,CONCATENATE(G$4,"-",$C6)) -> 59 | H6: =SUM(D6:G6) -> 1125 | K6: c_som_1_2 | L6: =+D6/D$14 -> 0.11530078 | M6: =+E6/E$14 -> 0.11969015 | N6: =+F6/F$14 -> 0.18530351 | O6: =+G6/G$14 -> 0.13625866
C7: c_som_1_3 | D7: =COUNTIF('Datos Segmentados'!M:M,CONCATENATE(D$4,"-",$C7)) -> 844 | E7: =COUNTIF('Datos Segmentados'!M:M,CONCATENATE(E$4,"-",$C7)) -> 389 | F7: =COUNTIF('Datos Segmentados'!M:M,CONCATENATE(F$4,"-",$C7)) -> 40 | G7: =COUNTIF('Datos Segmentados'!M:M,CONCATENATE(G$4,"-",$C7)) -> 81 | H7: =SUM(D7:G7) -> 1354 | K7: c_som_1_3 | L7: =+D7/D$14 -> 0.18395815 | M7: =+E7/E$14 -> 0.097201399 | N7: =+F7/F$14 -> 0.12779553 | O7: =+G7/G$14 -> 0.18706697
C8: c_som_2_1 | D8: =COUNTIF('Datos Segmentados'!M:M,CONCATENATE(D$4,"-",$C8)) -> 895 | E8: =COUNTIF('Datos Segmentados'!M:M,CONCATENATE(E$4,"-",$C8)) -> 856 | F8: =COUNTIF('Datos Segmentados'!M:M,CONCATENATE(F$4,"-",$C8)) -> 64 | G8: =COUNTIF('Datos Segmentados'!M:M,CONCATENATE(G$4,"-",$C8)) -> 76 | H8: =SUM(D8:G8) -> 1891 | K8: c_som_2_1 | L8: =+D8/D$14 -> 0.19507411 | M8: =+E8/E$14 -> 0.21389305 | N8: =+F8/F$14 -> 0.20447284 | O8: =+G8/G$14 -> 0.17551963
C9: c_som_2_2 | D9: =COUNTIF('Datos Segmentados'!M:M,CONCATENATE(D$4,"-",$C9)) -> 486 | E9: =COUNTIF('Datos Segmentados'!M:M,CONCATENATE(E$4,"-",$C9)) -> 430 | F9: =COUNTIF('Datos Segmentados'!M:M,CONCATENATE(F$4,"-",$C9)) -> 60 | G9: =COUNTIF('Datos Segmentados'!M:M,CONCATENATE(G$4,"-",$C9)) -> 77 | H9: =SUM(D9:G9) -> 1053 | K9: c_som_2_2 | L9: =+D9/D$14 -> 0.10592851 | M9: =+E9/E$14 -> 0.10744628 | N9: =+F9/F$14 -> 0.19169329 | O9: =+G9/G$14 -> 0.1778291
C10: c_som_2_3 | D10: =COUNTIF('Datos Segmentados'!M:M,CONCATENATE(D$4,"-",$C10)) -> 0 | E10: =COUNTIF('Datos Segmentados'!M:M,CONCATENATE(E$4,"-",$C10)) -> 0 | F10: =COUNTIF('Datos Segmentados'!M:M,CONCATENATE(F$4,"-",$C10)) -> 0 | G10: =COUNTIF('Datos Segmentados'!M:M,CONCATENATE(G$4,"-",$C10)) -> 0 | H10: =SUM(D10:G10) -> 0 | K10: c_som_2_3 | L10: =+D10/D$14 -> 0 | M10: =+E10/E$14 -> 0 | N10: =+F10/F$14 -> 0 | O10: =+G10/G$14 -> 0
C11: c_som_3_1 | D11: =COUNTIF('Datos Segmentados'!M:M,CONCATENATE(D$4,"-",$C11)) -> 509 | E11: =COUNTIF('Datos Segmentados'!M:M,CONCATENATE(E$4,"-",$C11)) -> 441 | F11: =COUNTIF('Datos Segmentados'!M:M,CONCATENATE(F$4,"-",$C11)) -> 13 | G11: =COUNTIF('Datos Segmentados'!M:M,CONCATENATE(G$4,"-",$C11)) -> 32 | H11: =SUM(D11:G11) -> 995 | K11: c_som_3_1 | L11: =+D11/D$14 -> 0.11094159 | M11: =+E11/E$14 -> 0.1101949 | N11: =+F11/F$14 -> 0.041533546 | O11: =+G11/G$14 -> 0.073903002
C12: c_som_3_2 | D12: =COUNTIF('Datos Segmentados'!M:M,CONCATENATE(D$4,"-",$C12)) -> 702 | E12: =COUNTIF('Datos Segmentados'!M:M,CONCATENATE(E$4,"-",$C12)) -> 701 | F12: =COUNTIF('Datos Segmentados'!M:M,CONCATENATE(F$4,"-",$C12)) -> 42 | G12: =COUNTIF('Datos Segmentados'!M:M,CONCATENATE(G$4,"-",$C12)) -> 55 | H12: =SUM(D12:G12) -> 1500 | K12: c_som_3_2 | L12: =+D12/D$14 -> 0.15300785 | M12: =+E12/E$14 -> 0.17516242 | N12: =+F12/F$14 -> 0.1341853 | O12: =+G12/G$14 -> 0.12702079
C13: c_som_3_3 | D13: =COUNTIF('Datos Segmentados'!M:M,CONCATENATE(D$4,"-",$C13)) -> 21 | E13: =COUNTIF('Datos Segmentados'!M:M,CONCATENATE(E$4,"-",$C13)) -> 0 | F13: =COUNTIF('Datos Segmentados'!M:M,CONCATENATE(F$4,"-",$C13)) -> 0 | G13: =COUNTIF('Datos Segmentados'!M:M,CONCATENATE(G$4,"-",$C13)) -> 0 | H13: =SUM(D13:G13) -> 21 | K13: c_som_3_3 | L13: =+D13/D$14 -> 0.0045771578 | M13: =+E13/E$14 -> 0 | N13: =+F13/F$14 -> 0 | O13: =+G13/G$14 -> 0
D14: =SUM(D5:D13) -> 4588 | E14: =SUM(E5:E13) -> 4002 | F14: =SUM(F5:F13) -> 313 | G14: =SUM(G5:G13) -> 433 | H14: =SUM(H5:H13) -> 9336
B19: Parrilla de Elementos (formateada)
D21: TURNO-TERMINADO | E21: SOBRETURNO-TERMINADO | F21: SOBRETURNO-SUSPENDIDO | G21: TURNO-SUSPENDIDO
C22: c_som_1_1 | D22: =ROUND(L5*10,0) -> 1 | E22: =ROUND(M5*10,0) -> 2 | F22: =ROUND(N5*10,0) -> 1 | G22: =ROUND(O5*10,0) -> 1
C23: c_som_1_2 | D23: =ROUND(L6*10,0) -> 1 | E23: =ROUND(M6*10,0) -> 1 | F23: =ROUND(N6*10,0) -> 2 | G23: =ROUND(O6*10,0) -> 1
C24: c_som_1_3 | D24: =ROUND(L7*10,0) -> 2 | E24: =ROUND(M7*10,0) -> 1 | F24: =ROUND(N7*10,0) -> 1 | G24: =ROUND(O7*10,0) -> 2
C25: c_som_2_1 | D25: =ROUND(L8*10,0) -> 2 | E25: =ROUND(M8*10,0) -> 2 | F25: =ROUND(N8*10,0) -> 2 | G25: =ROUND(O8*10,0) -> 2
C26: c_som_2_2 | D26: =ROUND(L9*10,0) -> 1 | E26: =ROUND(M9*10,0) -> 1 | F26: =ROUND(N9*10,0) -> 2 | G26: =ROUND(O9*10,0) -> 2
C27: c_som_2_3 | D27: =ROUND(L10*10,0) -> 0 | E27: =ROUND(M10*10,0) -> 0 | F27: =ROUND(N10*10,0) -> 0 | G27: =ROUND(O10*10,0) -> 0
C28: c_som_3_1 | D28: =ROUND(L11*10,0) -> 1 | E28: =ROUND(M11*10,0) -> 1 | F28: =ROUND(N11*10,0) -> 0 | G28: =ROUND(O11*10,0) -> 1
C29: c_som_3_2 | D29: =ROUND(L12*10,0) -> 2 | E29: =ROUND(M12*10,0) -> 2 | F29: =ROUND(N12*10,0) -> 1 | G29: =ROUND(O12*10,0) -> 1
C30: c_som_3_3 | D30: =ROUND(L13*10,0) -> 0 | E30: =ROUND(M13*10,0) -> 0 | F30: =ROUND(N13*10,0) -> 0 | G30: =ROUND(O13*10,0) -> 0

Sheet Res NaiveBayes
B1: Supervised Learning 1 (Naive bayes)
B2: Parameters
B4: Parameters
B5: Use laplacian | D5: 1
B6: Lambda for laplacian | D6: 1
B7: Show conditional probabilities | D7: 1
B8: Show model description | D8: 1
B11: Results
B13: Classifier performances
B15: Error rate | E15: 0.2345
B16: Values prediction | E16: Confusion matrix
B17: Value | C17: Recall | D17: 1-Precision | F17: c_som_1_1 | G17: c_som_1_2 | H17: c_som_1_3 | I17: c_som_2_1 | J17: c_som_2_2 | K17: c_som_2_3 | L17: c_som_3_1 | M17: c_som_3_2 | N17: c_som_3_3 | O17: Sum
B18: c_som_1_1 | C18: 0.8568 | D18: 0.3372 | E18: c_som_1_1 | F18: 1197 | G18: 0 | H18: 0 | I18: 42 | J18: 0 | K18: 0 | L18: 158 | M18: 0 | N18: 0 | O18: 1397
B19: c_som_1_2 | C19: 0.3396 | D19: 0.0969 | E19: c_som_1_2 | F19: 0 | G19: 382 | H19: 47 | I19: 0 | J19: 0 | K19: 0 | L19: 674 | M19: 22 | N19: 0 | O19: 1125
B20: c_som_1_3 | C20: 0.6448 | D20: 0.0772 | E20: c_som_1_3 | F20: 0 | G20: 16 | H20: 873 | I20: 276 | J20: 0 | K20: 0 | L20: 0 | M20: 189 | N20: 0 | O20: 1354
B21: c_som_2_1 | C21: 0.9339 | D21: 0.1622 | E21: c_som_2_1 | F21: 44 | G21: 0 | H21: 0 | I21: 1766 | J21: 0 | K21: 0 | L21: 0 | M21: 81 | N21: 0 | O21: 1891
B22: c_som_2_2 | C22: 0.3922 | D22: 0 | E22: c_som_2_2 | F22: 565 | G22: 25 | H22: 26 | I22: 24 | J22: 413 | K22: 0 | L22: 0 | M22: 0 | N22: 0 | O22: 1053
B23: c_som_2_3 | C23: 0 | D23: 1 | E23: c_som_2_3 | F23: 0 | G23: 0 | H23: 0 | I23: 0 | J23: 0 | K23: 0 | L23: 0 | M23: 0 | N23: 0 | O23: 0
B24: c_som_3_1 | C24: 1 | D24: 0.4554 | E24: c_som_3_1 | F24: 0 | G24: 0 | H24: 0 | I24: 0 | J24: 0 | K24: 0 | L24: 995 | M24: 0 | N24: 0 | O24: 995
B25: c_som_3_2 | C25: 1 | D25: 0.1629 | E25: c_som_3_2 | F25: 0 | G25: 0 | H25: 0 | I25: 0 | J25: 0 | K25: 0 | L25: 0 | M25: 1500 | N25: 0 | O25: 1500
B26: c_som_3_3 | C26: 1 | D26: 0 | E26: c_som_3_3 | F26: 0 | G26: 0 | H26: 0 | I26: 0 | J26: 0 | K26: 0 | L26: 0 | M26: 0 | N26: 21 | O26: 21
E27: Sum | F27: 1806 | G27: 423 | H27: 946 | I27: 2108 | J27: 413 | K27: 0 | L27: 1827 | M27: 1792 | N27: 21 | O27: 9336
B30: Classifier characteristics
B32: Data description
B34: Target attribute | C34: Cluster_SOM_1 (9 values)
B35: # descriptors | C35: 4
B37: Prior distribution of class attribute "Cluster_SOM_1"
B39: Values | C39: Count | D39: Percent | E39: Histogram
B40: c_som_1_1 | C40: 1397 | D40: 0.1496
B41: c_som_1_2 | C41: 1125 | D41: 0.1205
B42: c_som_1_3 | C42: 1354 | D42: 0.145
B43: c_som_2_1 | C43: 1891 | D43: 0.2025
B44: c_som_2_2 | C44: 1053 | D44: 0.1128
B45: c_som_2_3 | C45: 0 | D45: 0
B46: c_som_3_1 | C46: 995 | D46: 0.1066
B47: c_som_3_2 | C47: 1500 | D47: 0.1607
B48: c_som_3_3 | C48: 21 | D48: 0.0022
B50: Model description
C52: Classification functions
B53: Descriptors | C53: c_som_1_1 | D53: c_som_1_2 | E53: c_som_1_3 | F53: c_som_2_1 | G53: c_som_2_2 | H53: c_som_2_3 | I53: c_som_3_1 | J53: c_som_3_2 | K53: c_som_3_3
...

Sheet Parrilla  de Caracteristicas
B2: Probabilidades Condicionales para cada Característica y Cluster SOM:
C3: 5 | D3: 0 | E3: 1 | F3: 2 | G3: 3 | H3: 4 | I3: 5 | J3: 6 | K3: 7 | L3: 8
C4: Directa (1er polo) | D4: c_som_1_1 | E4: c_som_1_2 | F4: c_som_1_3 | G4: c_som_2_1 | H4: c_som_2_2 | I4: c_som_2_3 | J4: c_som_3_1 | K4: c_som_3_2 | L4: c_som_3_3
B5: 2 | C5: fecha-mes | D5: =OFFSET('Res NaiveBayes'!$B$115,$C$3,$B5+D$3) -> 0.0301 | E5: =OFFSET('Res NaiveBayes'!$B$115,$C$3,$B5+E$3) -> 0.0613 | F5: =OFFSET('Res NaiveBayes'!$B$115,$C$3,$B5+F$3) -> 0.9882 | G5: =OFFSET('Res NaiveBayes'!$B$115,$C$3,$B5+G$3) -> 0.9767 | H5: =OFFSET('Res NaiveBayes'!$B$115,$C$3,$B5+H$3) -> 0.0475 | I5: =OFFSET('Res NaiveBayes'!$B$115,$C$3,$B5+I$3) -> 0 | J5: =OFFSET('Res NaiveBayes'!$B$115,$C$3,$B5+J$3) -> 0 | K5: =OFFSET('Res NaiveBayes'!$B$115,$C$3,$B5+K$3) -> 1 | L5: =OFFSET('Res NaiveBayes'!$B$115,$C$3,$B5+L$3) -> 1
B6: 13 | C6: fecha-dia | D6: =OFFSET('Res NaiveBayes'!$B$115,$C$3,$B6+D$3) -> 0.8869 | E6: =OFFSET('Res NaiveBayes'!$B$115,$C$3,$B6+E$3) -> 0 | F6: =OFFSET('Res NaiveBayes'!$B$115,$C$3,$B6+F$3) -> 0.6064 | G6: =OFFSET('Res NaiveBayes'!$B$115,$C$3,$B6+G$3) -> 0.9572 | H6: =OFFSET('Res NaiveBayes'!$B$115,$C$3,$B6+H$3) -> 0.9763 | I6: =OFFSET('Res NaiveBayes'!$B$115,$C$3,$B6+I$3) -> 0 | J6: =OFFSET('Res NaiveBayes'!$B$115,$C$3,$B6+J$3) -> 0 | K6: =OFFSET('Res NaiveBayes'!$B$115,$C$3,$B6+K$3) -> 0 | L6: =OFFSET('Res NaiveBayes'!$B$115,$C$3,$B6+L$3) -> 0.2857
B7: 24 | C7: id_especialista | D7: =OFFSET('Res NaiveBayes'!$B$115,$C$3,$B7+D$3) -> 1 | E7: =OFFSET('Res NaiveBayes'!$B$115,$C$3,$B7+E$3) -> 1 | F7: =OFFSET('Res NaiveBayes'!$B$115,$C$3,$B7+F$3) -> 1 | G7: =OFFSET('Res NaiveBayes'!$B$115,$C$3,$B7+G$3) -> 1 | H7: =OFFSET('Res NaiveBayes'!$B$115,$C$3,$B7+H$3) -> 1 | I7: =OFFSET('Res NaiveBayes'!$B$115,$C$3,$B7+I$3) -> 0 | J7: =OFFSET('Res NaiveBayes'!$B$115,$C$3,$B7+J$3) -> 1 | K7: =OFFSET('Res NaiveBayes'!$B$115,$C$3,$B7+K$3) -> 1 | L7: =OFFSET('Res NaiveBayes'!$B$115,$C$3,$B7+L$3) -> 0
B8: 35 | C8: horario | D8: =OFFSET('Res NaiveBayes'!$B$115,$C$3,$B8+D$3) -> 0 | E8: =OFFSET('Res NaiveBayes'!$B$115,$C$3,$B8+E$3) -> 0.3813 | F8: =OFFSET('Res NaiveBayes'!$B$115,$C$3,$B8+F$3) -> 0.6566 | G8: =OFFSET('Res NaiveBayes'!$B$115,$C$3,$B8+G$3) -> 0 | H8: =OFFSET('Res NaiveBayes'!$B$115,$C$3,$B8+H$3) -> 0.4406 | I8: =OFFSET('Res NaiveBayes'!$B$115,$C$3,$B8+I$3) -> 0 | J8: =OFFSET('Res NaiveBayes'!$B$115,$C$3,$B8+J$3) -> 0 | K8: =OFFSET('Res NaiveBayes'!$B$115,$C$3,$B8+K$3) -> 0 | L8: =OFFSET('Res NaiveBayes'!$B$115,$C$3,$B8+L$3) -> 0
C10: =+C3+1 -> 6
C11: Opuesta (2do polo) | D11: =+D4 -> c_som_1_1 | E11: =+E4 -> c_som_1_2 | F11: =+F4 -> c_som_1_3 | G11: =+G4 -> c_som_2_1 | H11: =+H4 -> c_som_2_2 | I11: =+I4 -> c_som_2_3 | J11: =+J4 -> c_som_3_1 | K11: =+K4 -> c_som_3_2 | L11: =+L4 -> c_som_3_3
C12: fecha-mes | D12: =OFFSET('Res NaiveBayes'!$B$115,$C$10,$B5+D$3) -> 0.9699 | E12: =OFFSET('Res NaiveBayes'!$B$115,$C$10,$B5+E$3) -> 0.9387 | F12: =OFFSET('Res NaiveBayes'!$B$115,$C$10,$B5+F$3) -> 0.0118 | G12: =OFFSET('Res NaiveBayes'!$B$115,$C$10,$B5+G$3) -> 0.0233 | H12: =OFFSET('Res NaiveBayes'!$B$115,$C$10,$B5+H$3) -> 0.9525 | I12: =OFFSET('Res NaiveBayes'!$B$115,$C$10,$B5+I$3) -> 0 | J12: =OFFSET('Res NaiveBayes'!$B$115,$C$10,$B5+J$3) -> 1 | K12: =OFFSET('Res NaiveBayes'!$B$115,$C$10,$B5+K$3) -> 0 | L12: =OFFSET('Res NaiveBayes'!$B$115,$C$10,$B5+L$3) -> 0
C13: fecha-dia | D13: =OFFSET('Res NaiveBayes'!$B$115,$C$10,$B6+D$3) -> 0.1131 | E13: =OFFSET('Res NaiveBayes'!$B$115,$C$10,$B6+E$3) -> 1 | F13: =OFFSET('Res NaiveBayes'!$B$115,$C$10,$B6+F$3) -> 0.3936 | G13: =OFFSET('Res NaiveBayes'!$B$115,$C$10,$B6+G$3) -> 0.0428 | H13: =OFFSET('Res NaiveBayes'!$B$115,$C$10,$B6+H$3) -> 0.0237 | I13: =OFFSET('Res NaiveBayes'!$B$115,$C$10,$B6+I$3) -> 0 | J13: =OFFSET('Res NaiveBayes'!$B$115,$C$10,$B6+J$3) -> 1 | K13: =OFFSET('Res NaiveBayes'!$B$115,$C$10,$B6+K$3) -> 1 | L13: =OFFSET('Res NaiveBayes'!$B$115,$C$10,$B6+L$3) -> 0.7143
C14: id_especialista | D14: =OFFSET('Res NaiveBayes'!$B$115,$C$10,$B7+D$3) -> 0 | E14: =OFFSET('Res NaiveBayes'!$B$115,$C$10,$B7+E$3) -> 0 | F14: =OFFSET('Res NaiveBayes'!$B$115,$C$10,$B7+F$3) -> 0 | G14: =OFFSET('Res NaiveBayes'!$B$115,$C$10,$B7+G$3) -> 0 | H14: =OFFSET('Res NaiveBayes'!$B$115,$C$10,$B7+H$3) -> 0 | I14: =OFFSET('Res NaiveBayes'!$B$115,$C$10,$B7+I$3) -> 0 | J14: =OFFSET('Res NaiveBayes'!$B$115,$C$10,$B7+J$3) -> 0 | K14: =OFFSET('Res NaiveBayes'!$B$115,$C$10,$B7+K$3) -> 0 | L14: =OFFSET('Res NaiveBayes'!$B$115,$C$10,$B7+L$3) -> 1
C15: horario | D15: =OFFSET('Res NaiveBayes'!$B$115,$C$10,$B8+D$3) -> 1 | E15: =OFFSET('Res NaiveBayes'!$B$115,$C$10,$B8+E$3) -> 0.6187 | F15: =OFFSET('Res NaiveBayes'!$B$115,$C$10,$B8+F$3) -> 0.3434 | G15: =OFFSET('Res NaiveBayes'!$B$115,$C$10,$B8+G$3) -> 1 | H15: =OFFSET('Res NaiveBayes'!$B$115,$C$10,$B8+H$3) -> 0.5594 | I15: =OFFSET('Res NaiveBayes'!$B$115,$C$10,$B8+I$3) -> 0 | J15: =OFFSET('Res NaiveBayes'!$B$115,$C$10,$B8+J$3) -> 1 | K15: =OFFSET('Res NaiveBayes'!$B$115,$C$10,$B8+K$3) -> 1 | L15: =OFFSET('Res NaiveBayes'!$B$115,$C$10,$B8+L$3) -> 1
C18: CHECK | D18: =+D4 -> c_som_1_1 | E18: =+E4 -> c_som_1_2 | F18: =+F4 -> c_som_1_3 | G18: =+G4 -> c_som_2_1 | H18: =+H4 -> c_som_2_2 | I18: =+I4 -> c_som_2_3 | J18: =+J4 -> c_som_3_1 | K18: =+K4 -> c_som_3_2 | L18: =+L4 -> c_som_3_3
C19: fecha-mes | D19: =+D5+D12 -> 1 | E19: =+E5+E12 -> 1 | F19: =+F5+F12 -> 1 | G19: =+G5+G12 -> 1 | H19: =+H5+H12 -> 1 | I19: =+I5+I12 -> 0 | J19: =+J5+J12 -> 1 | K19: =+K5+K12 -> 1 | L19: =+L5+L12 -> 1
C20: fecha-dia | D20: =+D6+D13 -> 1 | E20: =+E6+E13 -> 1 | F20: =+F6+F13 -> 1 | G20: =+G6+G13 -> 1 | H20: =+H6+H13 -> 1 | I20: =+I6+I13 -> 0 | J20: =+J6+J13 -> 1 | K20: =+K6+K13 -> 1 | L20: =+L6+L13 -> 1
C21: especialista_id | D21: =+D7+D14 -> 1 | E21: =+E7+E14 -> 1 | F21: =+F7+F14 -> 1 | G21: =+G7+G14 -> 1 | H21: =+H7+H14 -> 1 | I21: =+I7+I14 -> 0 | J21: =+J7+J14 -> 1 | K21: =+K7+K14 -> 1 | L21: =+L7+L14 -> 1
C22: horario | D22: =+D8+D15 -> 1 | E22: =+E8+E15 -> 1 | F22: =+F8+F15 -> 1 | G22: =+G8+G15 -> 1 | H22: =+H8+H15 -> 1 | I22: =+I8+I15 -> 0 | J22: =+J8+J15 -> 1 | K22: =+K8+K15 -> 1 | L22: =+L8+L15 -> 1
B25: Parrillas de Características (formateada)
C27: Directa (1er polo) | D27: =+D4 -> c_som_1_1 | E27: =+E4 -> c_som_1_2 | F27: =+F4 -> c_som_1_3 | G27: =+G4 -> c_som_2_1 | H27: =+H4 -> c_som_2_2 | I27: =+I4 -> c_som_2_3 | J27: =+J4 -> c_som_3_1 | K27: =+K4 -> c_som_3_2 | L27: =+L4 -> c_som_3_3
C28: =+C5 -> fecha-mes | D28: =ROUND(D5*10,0) -> 0 | E28: =ROUND(E5*10,0) -> 1 | F28: =ROUND(F5*10,0) -> 10 | G28: =ROUND(G5*10,0) -> 10 | H28: =ROUND(H5*10,0) -> 0 | I28: =ROUND(I5*10,0) -> 0 | J28: =ROUND(J5*10,0) -> 0 | K28: =ROUND(K5*10,0) -> 10 | L28: =ROUND(L5*10,0) -> 10
C29: =+C6 -> fecha-dia | D29: =ROUND(D6*10,0) -> 9 | E29: =ROUND(E6*10,0) -> 0 | F29: =ROUND(F6*10,0) -> 6 | G29: =ROUND(G6*10,0) -> 10 | H29: =ROUND(H6*10,0) -> 10 | I29: =ROUND(I6*10,0) -> 0 | J29: =ROUND(J6*10,0) -> 0 | K29: =ROUND(K6*10,0) -> 0 | L29: =ROUND(L6*10,0) -> 3
C30: id_especialista | D30: =ROUND(D7*10,0) -> 10 | E30: =ROUND(E7*10,0) -> 10 | F30: =ROUND(F7*10,0) -> 10 | G30: =ROUND(G7*10,0) -> 10 | H30: =ROUND(H7*10,0) -> 10 | I30: =ROUND(I7*10,0) -> 0 | J30: =ROUND(J7*10,0) -> 10 | K30: =ROUND(K7*10,0) -> 10 | L30: =ROUND(L7*10,0) -> 0
C31: =+C8 -> horario | D31: =ROUND(D8*10,0) -> 0 | E31: =ROUND(E8*10,0) -> 4 | F31: =ROUND(F8*10,0) -> 7 | G31: =ROUND(G8*10,0) -> 0 | H31: =ROUND(H8*10,0) -> 4 | I31: =ROUND(I8*10,0) -> 0 | J31: =ROUND(J8*10,0) -> 0 | K31: =ROUND(K8*10,0) -> 0 | L31: =ROUND(L8*10,0) -> 0
C34: Opuesta (2do polo) | D34: =+D11 -> c_som_1_1 | E34: =+E11 -> c_som_1_2 | F34: =+F11 -> c_som_1_3 | G34: =+G11 -> c_som_2_1 | H34: =+H11 -> c_som_2_2 | I34: =+I11 -> c_som_2_3 | J34: =+J11 -> c_som_3_1 | K34: =+K11 -> c_som_3_2 | L34: =+L11 -> c_som_3_3
C35: =+C12 -> fecha-mes | D35: =ROUND(D12*10,0) -> 10 | E35: =ROUND(E12*10,0) -> 9 | F35: =ROUND(F12*10,0) -> 0 | G35: =ROUND(G12*10,0) -> 0 | H35: =ROUND(H12*10,0) -> 10 | I35: =ROUND(I12*10,0) -> 0 | J35: =ROUND(J12*10,0) -> 10 | K35: =ROUND(K12*10,0) -> 0 | L35: =ROUND(L12*10,0) -> 0
C36: =+C13 -> fecha-dia | D36: =ROUND(D13*10,0) -> 1 | E36: =ROUND(E13*10,0) -> 10 | F36: =ROUND(F13*10,0) -> 4 | G36: =ROUND(G13*10,0) -> 0 | H36: =ROUND(H13*10,0) -> 0 | I36: =ROUND(I13*10,0) -> 0 | J36: =ROUND(J13*10,0) -> 10 | K36: =ROUND(K13*10,0) -> 10 | L36: =ROUND(L13*10,0) -> 7
C37: id_especialista | D37: =ROUND(D14*10,0) -> 0 | E37: =ROUND(E14*10,0) -> 0 | F37: =ROUND(F14*10,0) -> 0 | G37: =ROUND(G14*10,0) -> 0 | H37: =ROUND(H14*10,0) -> 0 | I37: =ROUND(I14*10,0) -> 0 | J37: =ROUND(J14*10,0) -> 0 | K37: =ROUND(K14*10,0) -> 0 | L37: =ROUND(L14*10,0) -> 10
C38: =+C15 -> horario | D38: =ROUND(D15*10,0) -> 10 | E38: =ROUND(E15*10,0) -> 6 | F38: =ROUND(F15*10,0) -> 3 | G38: =ROUND(G15*10,0) -> 10 | H38: =ROUND(H15*10,0) -> 6 | I38: =ROUND(I15*10,0) -> 0 | J38: =ROUND(J15*10,0) -> 10 | K38: =ROUND(K15*10,0) -> 10 | L38: =ROUND(L15*10,0) -> 10

Sheet Distancias de Elementos
B2: Parrilla de Elementos:
D4: TURNO-TERMINADO | E4: SOBRETURNO-TERMINADO | F4: SOBRETURNO-SUSPENDIDO | G4: TURNO-SUSPENDIDO
C5: c_som_1_1 | D5: =+'Parrilla de Elementos'!D22 -> 1 | E5: =+'Parrilla de Elementos'!E22 -> 2 | F5: =+'Parrilla de Elementos'!F22 -> 1 | G5: =+'Parrilla de Elementos'!G22 -> 1
C6: c_som_1_2 | D6: =+'Parrilla de Elementos'!D23 -> 1 | E6: =+'Parrilla de Elementos'!E23 -> 1 | F6: =+'Parrilla de Elementos'!F23 -> 2 | G6: =+'Parrilla de Elementos'!G23 -> 1
C7: c_som_1_3 | D7: =+'Parrilla de Elementos'!D24 -> 2 | E7: =+'Parrilla de Elementos'!E24 -> 1 | F7: =+'Parrilla de Elementos'!F24 -> 1 | G7: =+'Parrilla de Elementos'!G24 -> 2
C8: c_som_2_1 | D8: =+'Parrilla de Elementos'!D25 -> 2 | E8: =+'Parrilla de Elementos'!E25 -> 2 | F8: =+'Parrilla de Elementos'!F25 -> 2 | G8: =+'Parrilla de Elementos'!G25 -> 2
C9: c_som_2_2 | D9: =+'Parrilla de Elementos'!D26 -> 1 | E9: =+'Parrilla de Elementos'!E26 -> 1 | F9: =+'Parrilla de Elementos'!F26 -> 2 | G9: =+'Parrilla de Elementos'!G26 -> 2
C10: c_som_2_3 | D10: =+'Parrilla de Elementos'!D27 -> 0 | E10: =+'Parrilla de Elementos'!E27 -> 0 | F10: =+'Parrilla de Elementos'!F27 -> 0 | G10: =+'Parrilla de Elementos'!G27 -> 0
C11: c_som_3_1 | D11: =+'Parrilla de Elementos'!D28 -> 1 | E11: =+'Parrilla de Elementos'!E28 -> 1 | F11: =+'Parrilla de Elementos'!F28 -> 0 | G11: =+'Parrilla de Elementos'!G28 -> 1
C12: c_som_3_2 | D12: =+'Parrilla de Elementos'!D29 -> 2 | E12: =+'Parrilla de Elementos'!E29 -> 2 | F12: =+'Parrilla de Elementos'!F29 -> 1 | G12: =+'Parrilla de Elementos'!G29 -> 1
C13: c_som_3_3 | D13: =+'Parrilla de Elementos'!D30 -> 0 | E13: =+'Parrilla de Elementos'!E30 -> 0 | F13: =+'Parrilla de Elementos'!F30 -> 0 | G13: =+'Parrilla de Elementos'!G30 -> 0
B15: Matriz de Distancias de Elementos:
D17: TURNO-TERMINADO | E17: SOBRETURNO-TERMINADO | F17: SOBRETURNO-SUSPENDIDO | G17: TURNO-SUSPENDIDO
C18: TURNO-TERMINADO | E18: 2 | F18: 5 | G18: 2
C19: SOBRETURNO-TERMINADO | F19: 5 | G19: 4
C20: SOBRETURNO-SUSPENDIDO | G20: 3
C21: TURNO-SUSPENDIDO

Sheet Distancias de Caracteristicas
B2: Parrillas de Características:
B4: =+'Parrilla de Caracteristicas'!C27 -> Directa (1er polo) | C4: =+'Parrilla de Caracteristicas'!D27 -> c_som_1_1 | D4: =+'Parrilla de Caracteristicas'!E27 -> c_som_1_2 | E4: =+'Parrilla de Caracteristicas'!F27 -> c_som_1_3 | F4: =+'Parrilla de Caracteristicas'!G27 -> c_som_2_1 | G4: =+'Parrilla de Caracteristicas'!H27 -> c_som_2_2 | H4: =+'Parrilla de Caracteristicas'!I27 -> c_som_2_3 | I4: =+'Parrilla de Caracteristicas'!J27 -> c_som_3_1 | ... K4: =+'Parrilla de Caracteristicas'!L27 -> c_som_3_3
B5: =+'Parrilla de Caracteristicas'!C28 -> fecha-mes | C5: =+'Parrilla de Caracteristicas'!D28 -> 0 | D5: =+'Parrilla de Caracteristicas'!E28 -> 1 | E5: =+'Parrilla de Caracteristicas'!F28 -> 10 | F5: =+'Parrilla de Caracteristicas'!G28 -> 10 | G5: =+'Parrilla de Caracteristicas'!H28 -> 0 | H5: =+'Parrilla de Caracteristicas'!I28 -> 0 | I5: =+'Parrilla de Caracteristicas'!J28 -> 0 | ... K5: =+'Parrilla de Caracteristicas'!L28 -> 10
B6: =+'Parrilla de Caracteristicas'!C29 -> fecha-dia | C6: =+'Parrilla de Caracteristicas'!D29 -> 9 | D6: =+'Parrilla de Caracteristicas'!E29 -> 0 | E6: =+'Parrilla de Caracteristicas'!F29 -> 6 | F6: =+'Parrilla de Caracteristicas'!G29 -> 10 | G6: =+'Parrilla de Caracteristicas'!H29 -> 10 | H6: =+'Parrilla de Caracteristicas'!I29 -> 0 | I6: =+'Parrilla de Caracteristicas'!J29 -> 0 | ... K6: =+'Parrilla de Caracteristicas'!L29 -> 3
B7: =+'Parrilla de Caracteristicas'!C30 -> id_especialista | C7: =+'Parrilla de Caracteristicas'!D30 -> 10 | D7: =+'Parrilla de Caracteristicas'!E30 -> 10 | E7: =+'Parrilla de Caracteristicas'!F30 -> 10 | F7: =+'Parrilla de Caracteristicas'!G30 -> 10 | G7: =+'Parrilla de Caracteristicas'!H30 -> 10 | H7: =+'Parrilla de Caracteristicas'!I30 -> 0 | I7: =+'Parrilla de Caracteristicas'!J30 -> 10 | ... K7: =+'Parrilla de Caracteristicas'!L30 -> 0
B8: =+'Parrilla de Caracteristicas'!C31 -> horario | C8: =+'Parrilla de Caracteristicas'!D31 -> 0 | D8: =+'Parrilla de Caracteristicas'!E31 -> 4 | E8: =+'Parrilla de Caracteristicas'!F31 -> 7 | F8: =+'Parrilla de Caracteristicas'!G31 -> 0 | G8: =+'Parrilla de Caracteristicas'!H31 -> 4 | H8: =+'Parrilla de Caracteristicas'!I31 -> 0 | I8: =+'Parrilla de Caracteristicas'!J31 -> 0 | ... K8: =+'Parrilla de Caracteristicas'!L31 -> 0
B11: =+'Parrilla de Caracteristicas'!C34 -> Opuesta (2do polo) | C11: =+'Parrilla de Caracteristicas'!D34 -> c_som_1_1 | D11: =+'Parrilla de Caracteristicas'!E34 -> c_som_1_2 | E11: =+'Parrilla de Caracteristicas'!F34 -> c_som_1_3 | F11: =+'Parrilla de Caracteristicas'!G34 -> c_som_2_1 | G11: =+'Parrilla de Caracteristicas'!H34 -> c_som_2_2 | H11: =+'Parrilla de Caracteristicas'!I34 -> c_som_2_3 | I11: =+'Parrilla de Caracteristicas'!J34 -> c_som_3_1 | ... K11: =+'Parrilla de Caracteristicas'!L34 -> c_som_3_3
B12: =+'Parrilla de Caracteristicas'!C35 -> fecha-mes | C12: =+'Parrilla de Caracteristicas'!D35 -> 10 | D12: =+'Parrilla de Caracteristicas'!E35 -> 9 | E12: =+'Parrilla de Caracteristicas'!F35 -> 0 | F12: =+'Parrilla de Caracteristicas'!G35 -> 0 | G12: =+'Parrilla de Caracteristicas'!H35 -> 10 | H12: =+'Parrilla de Caracteristicas'!I35 -> 0 | I12: =+'Parrilla de Caracteristicas'!J35 -> 10 | ... K12: =+'Parrilla de Caracteristicas'!L35 -> 0
B13: =+'Parrilla de Caracteristicas'!C36 -> fecha-dia | C13: =+'Parrilla de Caracteristicas'!D36 -> 1 | D13: =+'Parrilla de Caracteristicas'!E36 -> 10 | E13: =+'Parrilla de Caracteristicas'!F36 -> 4 | F13: =+'Parrilla de Caracteristicas'!G36 -> 0 | G13: =+'Parrilla de Caracteristicas'!H36 -> 0 | H13: =+'Parrilla de Caracteristicas'!I36 -> 0 | I13: =+'Parrilla de Caracteristicas'!J36 -> 10 | ... K13: =+'Parrilla de Caracteristicas'!L36 -> 7
B14: =+'Parrilla de Caracteristicas'!C37 -> id_especialista | C14: =+'Parrilla de Caracteristicas'!D37 -> 0 | D14: =+'Parrilla de Caracteristicas'!E37 -> 0 | E14: =+'Parrilla de Caracteristicas'!F37 -> 0 | F14: =+'Parrilla de Caracteristicas'!G37 -> 0 | G14: =+'Parrilla de Caracteristicas'!H37 -> 0 | H14: =+'Parrilla de Caracteristicas'!I37 -> 0 | I14: =+'Parrilla de Caracteristicas'!J37 -> 0 | ... K14: =+'Parrilla de Caracteristicas'!L37 -> 10
B15: =+'Parrilla de Caracteristicas'!C38 -> horario | C15: =+'Parrilla de Caracteristicas'!D38 -> 10 | D15: =+'Parrilla de Caracteristicas'!E38 -> 6 | E15: =+'Parrilla de Caracteristicas'!F38 -> 3 | F15: =+'Parrilla de Caracteristicas'!G38 -> 10 | G15: =+'Parrilla de Caracteristicas'!H38 -> 6 | H15: =+'Parrilla de Caracteristicas'!I38 -> 0 | I15: =+'Parrilla de Caracteristicas'!J38 -> 10 | ... K15: =+'Parrilla de Caracteristicas'!L38 -> 10
B17: Matriz de Distancias de Características:
C19: =+B21 -> fecha-dia | D19: =+B21 -> fecha-dia | E19: =+B22 -> id_especialista | F19: =+B23 -> horario
A20: C1 | B20: =+B5 -> fecha-mes | D20: 41 | E20: 49 | F20: 40
A21: C2 | B21: =+B6 -> fecha-dia | C21: 39 | E21: 38 | F21: 33
A22: C3 | B22: =+B7 -> id_especialista | C22: 31 | D22: 42 | F22: 55
A23: C4 | B23: =+B8 -> horario | C23: 38 | D23: 41 | E23: 25
B26: Matriz de Distancias de Características (Unificada):
C27: 0 | D27: 1 | E27: 2 | F27: 3
C28: =+C19 -> fecha-dia | D28: =+D19 -> fecha-dia | E28: =+E19 -> id_especialista | F28: =+F19 -> horario
A29: 0 | B29: =+B20 -> fecha-mes | D29: =MIN(OFFSET($C$20,$A29,D$27),OFFSET($C$20,D$27,$A29)) -> 39 | E29: =MIN(OFFSET($C$20,$A29,E$27),OFFSET($C$20,E$27,$A29)) -> 31 | F29: =MIN(OFFSET($C$20,$A29,F$27),OFFSET($C$20,F$27,$A29)) -> 38
A30: 1 | B30: =+B21 -> fecha-dia | E30: =MIN(OFFSET($C$20,$A30,E$27),OFFSET($C$20,E$27,$A30)) -> 38 | F30: =MIN(OFFSET($C$20,$A30,F$27),OFFSET($C$20,F$27,$A30)) -> 33
A31: 2 | B31: =+B22 -> id_especialista | F31: =MIN(OFFSET($C$20,$A31,F$27),OFFSET($C$20,F$27,$A31)) -> 25
A32: 3 | B32: =+B23 -> horario

Sheet auxi cuentas Caractersticas
B1: Directa (1er polo) | C1: c_som_1_1 | D1: c_som_1_2 | E1: c_som_1_3 | F1: c_som_2_1 | G1: c_som_2_2 | H1: c_som_2_3 | I1: c_som_3_1 | J1: c_som_3_2 | K1: c_som_3_3
A2: DIRECTA | B2: fecha-mes | C2: 0 | D2: 1 | E2: 10 | F2: 10 | G2: 0 | H2: 0 | I2: 0 | J2: 10 | K2: 10
A3: C2 | B3: fecha-dia | C3: 9 | D3: 0 | E3: 6 | F3: 10 | G3: 10 | H3: 0 | I3: 0 | J3: 0 | K3: 3
A4: C3 | B4: especialista_id | C4: 10 | D4: 10 | E4: 10 | F4: 10 | G4: 10 | H4: 0 | I4: 10 | J4: 10 | K4: 0
A5: C4 | B5: horario | C5: 0 | D5: 4 | E5: 7 | F5: 0 | G5: 4 | H5: 0 | I5: 0 | J5: 0 | K5: 0
A8: =SUM(C8:K8) -> 41 | B8: C1 - C2 | C8: =ABS(C2-C3) -> 9 | D8: =ABS(D2-D3) -> 1 | E8: =ABS(E2-E3) -> 4 | F8: =ABS(F2-F3) -> 0 | G8: =ABS(G2-G3) -> 10 | H8: =ABS(H2-H3) -> 0 | I8: =ABS(I2-I3) -> 0 | J8: =ABS(J2-J3) -> 10 | K8: =ABS(K2-K3) -> 7
A9: =SUM(C9:K9) -> 49 | B9: C1 - C3 | C9: =ABS(C2-C4) -> 10 | D9: =ABS(D2-D4) -> 9 | E9: =ABS(E2-E4) -> 0 | F9: =ABS(F2-F4) -> 0 | G9: =ABS(G2-G4) -> 10 | H9: =ABS(H2-H4) -> 0 | I9: =ABS(I2-I4) -> 10 | J9: =ABS(J2-J4) -> 0 | K9: =ABS(K2-K4) -> 10
A10: =SUM(C10:K10) -> 40 | B10: C1 - C4 | C10: =ABS(C2-C5) -> 0 | D10: =ABS(D2-D5) -> 3 | E10: =ABS(E2-E5) -> 3 | F10: =ABS(F2-F5) -> 10 | G10: =ABS(G2-G5) -> 4 | H10: =ABS(H2-H5) -> 0 | I10: =ABS(I2-I5) -> 0 | J10: =ABS(J2-J5) -> 10 | K10: =ABS(K2-K5) -> 10
A11: =SUM(C11:K11) -> 38 | B11: C2 - C3 | C11: =ABS(C3-C4) -> 1 | D11: =ABS(D3-D4) -> 10 | E11: =ABS(E3-E4) -> 4 | F11: =ABS(F3-F4) -> 0 | G11: =ABS(G3-G4) -> 0 | H11: =ABS(H3-H4) -> 0 | I11: =ABS(I3-I4) -> 10 | J11: =ABS(J3-J4) -> 10 | K11: =ABS(K3-K4) -> 3
A12: =SUM(C12:K12) -> 33 | B12: C2 - C4 | C12: =ABS(C3-C5) -> 9 | D12: =ABS(D3-D5) -> 4 | E12: =ABS(E3-E5) -> 1 | F12: =ABS(F3-F5) -> 10 | G12: =ABS(G3-G5) -> 6 | H12: =ABS(H3-H5) -> 0 | I12: =ABS(I3-I5) -> 0 | J12: =ABS(J3-J5) -> 0 | K12: =ABS(K3-K5) -> 3
A13: =SUM(C13:K13) -> 55 | B13: C3 - C4 | C13: =ABS(C4-C5) -> 10 | D13: =ABS(D4-D5) -> 6 | E13: =ABS(E4-E5) -> 3 | F13: =ABS(F4-F5) -> 10 | G13: =ABS(G4-G5) -> 6 | H13: =ABS(H4-H5) -> 0 | I13: =ABS(I4-I5) -> 10 | J13: =ABS(J4-J5) -> 10 | K13: =ABS(K4-K5) -> 0
B16: Opuesta (2do polo) | C16: c_som_1_1 | D16: c_som_1_2 | E16: c_som_1_3 | F16: c_som_2_1 | G16: c_som_2_2 | H16: c_som_2_3 | I16: c_som_3_1 | J16: c_som_3_2 | K16: c_som_3_3
B17: fecha-mes | C17: 10 | D17: 9 | E17: 0 | F17: 0 | G17: 10 | H17: 0 | I17: 10 | J17: 0 | K17: 0
B18: fecha-dia | C18: 1 | D18: 10 | E18: 4 | F18: 0 | G18: 0 | H18: 0 | I18: 10 | J18: 10 | K18: 7
B19: especialista_id | C19: 0 | D19: 0 | E19: 0 | F19: 0 | G19: 0 | H19: 0 | I19: 0 | J19: 0 | K19: 10
B20: horario | C20: 10 | D20: 6 | E20: 3 | F20: 10 | G20: 6 | H20: 0 | I20: 10 | J20: 10 | K20: 10
A23: =SUM(C23:K23) -> 39 | B23: C1 - C2' | C23: =ABS(C2-C18) -> 1 | D23: =ABS(D2-D18) -> 9 | E23: =ABS(E2-E18) -> 6 | F23: =ABS(F2-F18) -> 10 | G23: =ABS(G2-G18) -> 0 | H23: =ABS(H2-H18) -> 0 | I23: =ABS(I2-I18) -> 10 | J23: =ABS(J2-J18) -> 0 | K23: =ABS(K2-K18) -> 3
A24: =SUM(C24:K24) -> 31 | B24: C1 - C3' | C24: =ABS(C2-C19) -> 0 | D24: =ABS(D2-D19) -> 1 | E24: =ABS(E2-E19) -> 10 | F24: =ABS(F2-F19) -> 10 | G24: =ABS(G2-G19) -> 0 | H24: =ABS(H2-H19) -> 0 | I24: =ABS(I2-I19) -> 0 | J24: =ABS(J2-J19) -> 10 | K24: =ABS(K2-K19) -> 0
A25: =SUM(C25:K25) -> 38 | B25: C1 - C4' | C25: =ABS(C2-C20) -> 10 | D25: =ABS(D2-D20) -> 5 | E25: =ABS(E2-E20) -> 7 | F25: =ABS(F2-F20) -> 0 | G25: =ABS(G2-G20) -> 6 | H25: =ABS(H2-H20) -> 0 | I25: =ABS(I2-I20) -> 10 | J25: =ABS(J2-J20) -> 0 | K25: =ABS(K2-K20) -> 0
A26: =SUM(C26:K26) -> 42 | B26: C2 - C3' | C26: =ABS(C3-C19) -> 9 | D26: =ABS(D3-D19) -> 0 | E26: =ABS(E3-E19) -> 6 | F26: =ABS(F3-F19) -> 10 | G26: =ABS(G3-G19) -> 10 | H26: =ABS(H3-H19) -> 0 | I26: =ABS(I3-I19) -> 0 | J26: =ABS(J3-J19) -> 0 | K26: =ABS(K3-K19) -> 7
A27: =SUM(C27:K27) -> 41 | B27: C2 - C4' | C27: =ABS(C3-C20) -> 1 | D27: =ABS(D3-D20) -> 6 | E27: =ABS(E3-E20) -> 3 | F27: =ABS(F3-F20) -> 0 | G27: =ABS(G3-G20) -> 4 | H27: =ABS(H3-H20) -> 0 | I27: =ABS(I3-I20) -> 10 | J27: =ABS(J3-J20) -> 10 | K27: =ABS(K3-K20) -> 7
A28: =SUM(C28:K28) -> 25 | B28: C3 - C4' | C28: =ABS(C4-C20) -> 0 | D28: =ABS(D4-D20) -> 4 | E28: =ABS(E4-E20) -> 7 | F28: =ABS(F4-F20) -> 0 | G28: =ABS(G4-G20) -> 4 | H28: =ABS(H4-H20) -> 0 | I28: =ABS(I4-I20) -> 0 | J28: =ABS(J4-J20) -> 0 | K28: =ABS(K4-K20) -> 10

Sheet Interpretacion Elementos
A1: Interpretación de Elementos:
D3: TURNO-TERMINADO | E3: SOBRETURNO-TERMINADO | F3: SOBRETURNO-SUSPENDIDO | G3: TURNO-SUSPENDIDO
C4: TURNO-TERMINADO | E4: =+'Distancias de Elementos'!E18 -> 2 | F4: =+'Distancias de Elementos'!F18 -> 5 | G4: =+'Distancias de Elementos'!G18 -> 2 | I4: 3
C5: SOBRETURNO-TERMINADO | F5: =+'Distancias de Elementos'!F19 -> 5 | G5: =+'Distancias de Elementos'!G19 -> 4
C6: SOBRETURNO-SUSPENDIDO | G6: =+'Distancias de Elementos'!G20 -> 3 | I6: 2
C7: TURNO-SUSPENDIDO
I8: 1
C10: Agrupaciones: | D10: {TURNO-TERMINADO, TURNO-SUSPENDIDO, SOBRETURNO-TERMINADO}, {SOBRETURNO-SUSPENDIDO} | J10: TURNO- TERMINADO | K10: TURNO- SUSPENDIDO | L10: SOBRETURNO- TERMINADO | M10: SOBRETURNO- SUSPENDIDO
C12: Cardinalidad: | D12: Existen 2 grupos.
C14: Similitudes: | D14: Los turnos (terminados y suspendidos) y los sobreturnos terminados son más similares entre sí. Luego todos se unen con los sobreturnos suspendidos por lo que no hay mayor similitud entre ellos y el sobreturno suspendido.

Sheet Interpretacion Caracteristicas
A1: Interpretación de Características: | H1: 33
C3: =+'Distancias de Caracteristicas'!C28 -> fecha-dia | D3: =+'Distancias de Caracteristicas'!D28 -> fecha-dia | E3: =+'Distancias de Caracteristicas'!E28 -> id_especialista | F3: =+'Distancias de Caracteristicas'!F28 -> horario | H3: 32
B4: =+'Distancias de Caracteristicas'!B29 -> fecha-mes | D4: =+'Distancias de Caracteristicas'!D29 -> 39 | E4: =+'Distancias de Caracteristicas'!E29 -> 31 | F4: =+'Distancias de Caracteristicas'!F29 -> 38
B5: =+'Distancias de Caracteristicas'!B30 -> fecha-dia | E5: =+'Distancias de Caracteristicas'!E30 -> 38 | F5: =+'Distancias de Caracteristicas'!F30 -> 33 | H5: 31
B6: =+'Distancias de Caracteristicas'!B31 -> id_especialista | F6: =+'Distancias de Caracteristicas'!F31 -> 25
B7: =+'Distancias de Caracteristicas'!B32 -> horario | H7: 30
H9: 29
C11: Agrupaciones: | D11: {especialista_id, horario}, {fecha_mes}, {fecha_dia} | H11: 28
C13: Cardinalidad: | D13: Existen 3 grupos. | H13: 27
C15: Similitudes: | D15: El médico (especilista) se relaciona primero con el horario en el que atiende, luego se relaciona con el mes y por último con el día del turno. | H15: 26
H17: 25
H19: 24
H21: (…)
H23: 5
H25: 4
H27: 3
H29: 2
H31: 1
I33: ESPECIALISTA_ID | J33: HORARIO | K33: FECHA-MES | L33: FECHA-DÍA
